Workbook

Sheet Dk-Es Jun22 
A1: DINAK | G1: 30012020
A4: CODIGO DK | B4: PVP | C4: DESCRIP_COMERCIAL | D4: EAN13 ANTIGUO | E4: EAN 13 NUEVO | F4: Ø | G4: GAMA
A5: 030912701 | B5: 8.41 | C5: ABRAZ. SOMBRERETE DP 304 Ø125 | D5: 8432630337935 | E5: 8432630337935 | F5: 125 | G5: DP 304-304
A6: 030915701 | B6: 8.81 | C6: ABRAZ. SOMBRERETE DP 304 Ø150 | D6: 8432630337942 | E6: 8432630337942 | F6: 150 | G6: DP 304-304
A7: 030917701 | B7: 9.33 | C7: ABRAZ. SOMBRERETE DP 304 Ø175 | D7: 8432630337959 | E7: 8432630337959 | F7: 175 | G7: DP 304-304
A8: 030920701 | B8: 10.75 | C8: ABRAZ. SOMBRERETE DP 304 Ø200 | D8: 8432630337966 | E8: 8432630337966 | F8: 200 | G8: DP 304-304
A9: 030925701 | B9: 12.9 | C9: ABRAZ. SOMBRERETE DP 304 Ø250 | D9: 8432630337973 | E9: 8432630337973 | F9: 250 | G9: DP 304-304
A10: 030930701 | B10: 14.3 | C10: ABRAZ. SOMBRERETE DP 304 Ø300 | D10: 8432630337980 | E10: 8432630337980 | F10: 300 | G10: DP 304-304
A11: 030935701 | B11: 24.33 | C11: ABRAZ. SOMBRERETE DP 304 Ø350 | D11: 8432630337997 | E11: 8432630337997 | F11: 350 | G11: DP 304-304
A12: 030940701 | B12: 25.8 | C12: ABRAZ. SOMBRERETE DP 304 Ø400 | D12: 8432630338000 | E12: 8432630338000 | F12: 400 | G12: DP 304-304
A13: 030945701 | B13: 28.6 | C13: ABRAZ. SOMBRERETE DP 304 Ø450 | D13: 8432630338017 | E13: 8432630338017 | F13: 450 | G13: DP 304-304
A14: 030912110 | B14: 32.72 | C14: ABRAZ. VIENTOS DP 304 Ø125 | D14: 8432630074694 | E14: 8432630074694 | F14: 125 | G14: DP 304-304
A15: 030915110 | B15: 32.72 | C15: ABRAZ. VIENTOS DP 304 Ø150 | D15: 8432630075691 | E15: 8432630075691 | F15: 150 | G15: DP 304-304
A16: 030917110 | B16: 34.75 | C16: ABRAZ. VIENTOS DP 304 Ø175 | D16: 8432630076681 | E16: 8432630076681 | F16: 175 | G16: DP 304-304
... A55: 030960070 | B55: 51.13 | C55: ABRAZADERA DE UNION DP 304 Ø600 | D55: 8432630086604 | E55: 8432630086604 | F55: 600 | G55: DP 304-304
A56: 030045100 | B56: 219.75 | C56: ADAPTADOR CALDERA Ø450 DA453 | D56: 8432630022701 | E56: 8432630022701 | F56: - | G56: DP 304-304 | H56: =+CONCATENATE(A56,"DW") -> 030045100DW | I56: =+VLOOKUP(H56,[1]España!$A$1:$B$1048576,2,0) -> 219.75
A57: 030050100 | B57: 262.9 | C57: ADAPTADOR CALDERA Ø500 DA503 | D57: 8432630024880 | E57: 8432630024880 | F57: - | G57: DP 304-304 | H57: =+CONCATENATE(A57,"DW") -> 030050100DW | I57: =+VLOOKUP(H57,[1]España!$A$1:$B$1048576,2,0) -> 262.9
A58: 030055100 | B58: 282.55 | C58: ADAPTADOR CALDERA Ø550 DA553 | D58: 8432630027034 | E58: 8432630027034 | F58: - | G58: DP 304-304 | H58: =+CONCATENATE(A58,"DW") -> 030055100DW | I58: =+VLOOKUP(H58,[1]España!$A$1:$B$1048576,2,0) -> 282.55
A59: 030016100 | B59: 40.17 | C59: ADAPTADOR CALDERA Ø600 DA603 | D59: - | E59: - | F59: - | G59: DP 304-304 | H59: 030016100DW | I59: =+VLOOKUP(H59,[1]España!$A$1:$B$1048576,2,0) -> #N/A
A60: 03004516Q | B60: 302.73 | C60: ADAPTADOR DP A SW Ø450 | D60: 8432630612872 | E60: 8432630612872 | F60: 450 | G60: DP 304-304
A61: 03005016Q | B61: 351,12 | C61: ADAPTADOR DP A SW Ø500 | D61: 8432630612865 | E61: 8432630612865 | F61: 500 | G61: DP 304-304
A62: 03005516Q | B62: 421.17 | C62: ADAPTADOR DP A SW Ø550 | D62: 8432630518693 | E62: 8432630518693 | F62: 550 | G62: DP 304-304
A63: 03006016Q | B63: 498.04 | C63: ADAPTADOR DP A SW Ø600 | D63: 8432630792284 | E63: 8432630792284 | F63: 600 | G63: DP 304-304
A64: 03904515PSW | B64: 202.47 | C64: ADAPTADOR SW A DP Ø450 | D64: 8432630739852 | E64: 8432630739852 | F64: 450 | G64: DP 304-304
A65: 03905015PSW | B65: 278.4 | C65: ADAPTADOR SW A DP Ø500 | D65: 8432630562573 | E65: 8432630562573 | F65: 500 | G65: DP 304-304
A66: 03905515PSW | B66: 303.16 | C66: ADAPTADOR SW A DP Ø550 | D66: 8432630518648 | E66: 8432630518648 | F66: 550 | G66: DP 304-304
A67: 03906015PSW | B67: 321.7 | C67: ADAPTADOR SW A DP Ø600 | D67: 8432630792277 | E67: 8432630792277 | F67: 600 | G67: DP 304-304
A68: 030912902 | B68: 75.93 | C68: ANCL. A FORJADO DOBLE 90º DP 304 Ø125 | D68: 8432630353690 | E68: 8432630353690 | F68: 125 | G68: DP 304-304
A69: 030915902 | B69: 77.81 | C69: ANCL. A FORJADO DOBLE 90º DP 304 Ø150 | D69: 8432630353706 | E69: 8432630353706 | F69: 150 | G69: DP 304-304
A70: 030917902 | B70: 80.97 | C70: ANCL. A FORJADO DOBLE 90º DP 304 Ø175 | D70: 8432630363835 | E70: 8432630363835 | F70: 175 | G70: DP 304-304
A71: 030920902 | B71: 83.52 | C71: ANCL. A FORJADO DOBLE 90º DP 304 Ø200 | D71: 8432630363415 | E71: 8432630363415 | F71: 200 | G71: DP 304-304
A72: 030925902 | B72: 87.21 | C72: ANCL. A FORJADO DOBLE 90º DP 304 Ø250 | D72: 8432630363842 | E72: 8432630363842 | F72: 250 | G72: DP 304-304
A73: 030930902 | B73: 90.9 | C73: ANCL. A FORJADO DOBLE 90º DP 304 Ø300 | D73: 8432630360384 | E73: 8432630360384 | F73: 300 | G73: DP 304-304
... A81: 030915901 | B81: 40.96 | C81: ANCL. A FORJADO PLANO DP 304 Ø150 | D81: 8432630179689 | E81: 8432630179689 | F81: 150 | G81: DP 304-304
A82: 030917901 | B82: 42,62 | C82: ANCL. A FORJADO PLANO DP 304 Ø175 | D82: 8432630179696 | E82: 8432630179696 | F82: 175 | G82: DP 304-304
A83: 030920901 | B83: 43.96 | C83: ANCL. A FORJADO PLANO DP 304 Ø200 | D83: 8432630179702 | E83: 8432630179702 | F83: 200 | G83: DP 304-304
A84: 030925901 | B84: 45.88 | C84: ANCL. A FORJADO PLANO DP 304 Ø250 | D84: 8432630179719 | E84: 8432630179719 | F84: 250 | G84: DP 304-304
A85: 030930901 | B85: 47.84 | C85: ANCL. A FORJADO PLANO DP 304 Ø300 | D85: 8432630179726 | E85: 8432630179726 | F85: 300 | G85: DP 304-304
A86: 030935901 | B86: 50.5 | C86: ANCL. A FORJADO PLANO DP 304 Ø350 | D86: 8432630179733 | E86: 8432630179733 | F86: 350 | G86: DP 304-304
A87: 030940901 | B87: 52.77 | C87: ANCL. A FORJADO PLANO DP 304 Ø400 | D87: 8432630179740 | E87: 8432630179740 | F87: 400 | G87: DP 304-304
...
